Workbook

Sheet Cover
B2: InvestPuppy · Investor Financial Model
B3: Vektor — Systematic Listed Equity Portfolio Management
B6: Version | C6: 1.2 · May 2026 — pricing updated
B7: Currency | C7: USD throughout
B8: Scenario tabs | C8: Base · Bear · Bull
B9: Raise target | C9: US$2.5M
B10: Pre-money range | C10: US$9M – US$10M
B11: Team | C11: CEO + CTO + 3 pre-launch collaborators (5 total)
B12: Status | C12: Pre-revenue · building toward first Proof Partner
B14: COLOUR CODING
B15: Blue text | C15: Hardcoded inputs — edit these to change scenarios
B16: Black text | C16: Formulas and calculations — do not edit
B17: Green text | C17: Cross-sheet links
B18: Yellow bg | C18: Key assumptions requiring attention
B20: THREE DELIVERY MODELS — REVENUE STREAMS
B21: Vektor : Boutique | C21: AUM-tiered annual subscription · direct to boutique DPMs, RIAs, family offices
B22: Vektor : House | C22: Institutional subscription · Alloy Partners programme · staged and gated engagement
B23: Vektor : Wrapped | C23: Licensing via custodian banks and wealth platforms · per-mandate + platform fee
B25: Internal only · Not for distribution · InvestPuppy Pte Ltd · May 2026
B27: Tenzor Scenario | C27: NDA-stage institutional product roadmap — combined Vektor + Tenzor scenario. Development begins post first Vektor Proof Partners go-live. Series A funded.

Sheet Assumptions
B1: ASSUMPTIONS | C1: BASE | D1: BEAR | E1: BULL
B3: PRICING (USD/year) — all scenarios identical (locked)
B4: Proof Partners Tier A rate (<US$55M AUM) | C4: 13500 | D4: 13500 | E4: 13500
B5: Proof Partners Tier B rate (>US$55M AUM, 35% below Growth tier) | C5: 23400 | D5: 23400 | E5: 23400 | F5: Growth tier x 0.65 - Year 1 preferential rate locked for duration
B6: Entry tier | C6: 18000 | D6: 18000 | E6: 18000
B7: Growth tier | C7: 36000 | D7: 36000 | E7: 36000
B8: Institutional tier | C8: 105000 | D8: 105000 | E8: 105000
B9: Enterprise tier (from) | C9: 175000 | D9: 175000 | E9: 175000
B10: Bloomberg Terminal ref | C10: 31980 | D10: 31980 | E10: 31980
B12: AUM TIER THRESHOLDS (USD millions)
B13: Entry threshold (≤) | C13: 55 | D13: 55 | E13: 55
B14: Growth threshold | C14: 185 | D14: 185 | E14: 185
B15: Institutional threshold | C15: 550 | D15: 550 | E15: 550
B17: VEKTOR : BOUTIQUE — CLIENT RAMP (cumulative end of year)
C18: BASE | D18: BEAR | E18: BULL
B19: Proof Partners (12-month founding rate) — Year 1 | C19: 3 | D19: 2 | E19: 5 | F19: Split between Tier A and Tier B clients to be specified as PP conversations progress
B20: Proof Partners (12-month founding rate) — Year 2 | C20: 3 | D20: 2 | E20: 5
B21: Proof Partners (12-month founding rate) — Year 3 | C21: 3 | D21: 2 | E21: 5
B22: Proof Partners (12-month founding rate) — Year 4 | C22: 0 | D22: 0 | E22: 0
B23: Proof Partners (12-month founding rate) — Year 5 | C23: 0 | D23: 0 | E23: 0
B24: Entry clients — Year 1 | C24: 2 | D24: 1 | E24: 4
B25: Entry clients — Year 2 | C25: 5 | D25: 3 | E25: 8
B26: Entry clients — Year 3 | C26: 8 | D26: 5 | E26: 14
B27: Entry clients — Year 4 | C27: 11 | D27: 7 | E27: 20
B28: Entry clients — Year 5 | C28: 14 | D28: 9 | E28: 26
B29: Growth clients — Year 1 | C29: 0 | D29: 0 | E29: 1
B30: Growth clients — Year 2 | C30: 1 | D30: 0 | E30: 2
B31: Growth clients — Year 3 | C31: 3 | D31: 1 | E31: 5
... B43: Enterprise clients — Year 5 | C43: 2 | D43: 1 | E43: 3
B45: VEKTOR : HOUSE — ALLOY PARTNERS RAMP (cumulative)
B46: Stage 1 conversations — Year 1 | C46: 2 | D46: 1 | E46: 3
B47: Stage 1 conversations — Year 2 | C47: 0 | D47: 0 | E47: 0
B48: Stage 1 conversations — Year 3 | C48: 0 | D48: 0 | E48: 0
B49: Stage 1 conversations — Year 4 | C49: 0 | D49: 0 | E49: 0
B50: Stage 1 conversations — Year 5 | C50: 0 | D50: 0 | E50: 0
B51: Stage 2 active — Year 1 | C51: 0 | D51: 0 | E51: 0
B52: Stage 2 active — Year 2 | C52: 1 | D52: 0 | E52: 1
B53: Stage 2 active — Year 3 | C53: 0 | D53: 0 | E53: 0
B54: Stage 2 active — Year 4 | C54: 0 | D54: 0 | E54: 0
B55: Stage 2 active — Year 5 | C55: 0 | D55: 0 | E55: 0
...

Sheet Base Case
B1: VEKTOR — BASE CASE | C1: Year 1 (2026) | D1: Year 2 (2027) | E1: Year 3 (2028) | F1: Year 4 (2029) | G1: Year 5 (2030)
B3: VEKTOR : BOUTIQUE — ANNUAL RECURRING REVENUE (USD)
B4: Proof Partners | C4: 40500 | D4: 40500 | E4: 40500 | F4: 0 | G4: 0
B5: Entry | C5: 36000 | D5: 90000 | E5: 144000 | F5: 198000 | G5: 252000
B6: Growth | C6: 0 | D6: 36000 | E6: 108000 | F6: 180000 | G6: 288000
B7: Institutional | C7: 0 | D7: 0 | E7: 105000 | F7: 210000 | G7: 420000
B8: Enterprise | C8: 0 | D8: 0 | E8: 0 | F8: 175000 | G8: 350000
B9: Boutique ARR Total | C9: =SUM(C4:C8) -> 76500 | D9: =SUM(D4:D8) -> 166500 | E9: =SUM(E4:E8) -> 397500 | F9: =SUM(F4:F8) -> 763000 | G9: =SUM(G4:G8) -> 1310000
B11: VEKTOR : HOUSE — ANNUAL RECURRING REVENUE (USD)
B12: Commercial clients (Alloy Partners) | C12: 0 | D12: 0 | E12: 250000 | F12: 500000 | G12: 750000
B13: House ARR Total | C13: =C12 -> 0 | D13: =D12 -> 0 | E13: =E12 -> 250000 | F13: =F12 -> 500000 | G13: =G12 -> 750000
B15: VEKTOR : WRAPPED — LICENCE REVENUE (USD)
B16: Platform licence fees | C16: 0 | D16: 0 | E16: 150000 | F16: 150000 | G16: 300000
B17: Per-mandate fees | C17: 0 | D17: 0 | E17: 80000 | F17: 80000 | G17: 160000
B18: Wrapped Revenue Total | C18: =C16+C17 -> 0 | D18: =D16+D17 -> 0 | E18: =E16+E17 -> 230000 | F18: =F16+F17 -> 230000 | G18: =G16+G17 -> 460000
B20: TOTAL ARR (USD)
B21: Total ARR | C21: =C9+C13+C18 -> 76500 | D21: =D9+D13+D18 -> 166500 | E21: =E9+E13+E18 -> 877500 | F21: =F9+F13+F18 -> 1493000 | G21: =G9+G13+G18 -> 2520000
B23: OPERATING COSTS (USD) — constant across years (update as needed)
B24: Total operating costs | C24: 1180000 | D24: 1298000 | E24: 1495550 | F24: 1792380 | G24: 2154276
B25: EBITDA | C25: =C21-C24 -> -1103500 | D25: =D21-D24 -> -1131500 | E25: =E21-E24 -> -618050 | F25: =F21-F24 -> -299380 | G25: =G21-G24 -> 365724
B26: EBITDA margin | C26: =IF(C21=0,"n/m",C25/C21) -> -14.424837 | D26: =IF(D21=0,"n/m",D25/D21) -> -6.7957958 | E26: =IF(E21=0,"n/m",E25/E21) -> -0.70433048 | F26: =IF(F21=0,"n/m",F25/F21) -> -0.20052244 | G26: =IF(G21=0,"n/m",G25/G21) -> 0.14512857
B28: RAISE — CONTEXT
B29: Raise target | C29: US$2.5M
B30: Pre-money range | C30: US$9M – US$10M
B31: Runway (base case) | C31: 18–24 months post-raise
B32: Use of proceeds | C32: 5-person team · institutional sales cycle · legal infrastructure · Tenzor design phase

Sheet Bear Case
B1: VEKTOR — BEAR CASE | C1: Year 1 (2026) | D1: Year 2 (2027) | E1: Year 3 (2028) | F1: Year 4 (2029) | G1: Year 5 (2030)
B3: VEKTOR : BOUTIQUE — ANNUAL RECURRING REVENUE (USD)
B4: Proof Partners | C4: 27000 | D4: 27000 | E4: 27000 | F4: 0 | G4: 0
B5: Entry | C5: 18000 | D5: 54000 | E5: 90000 | F5: 126000 | G5: 162000
B6: Growth | C6: 0 | D6: 0 | E6: 36000 | F6: 72000 | G6: 144000
B7: Institutional | C7: 0 | D7: 0 | E7: 0 | F7: 105000 | G7: 210000
B8: Enterprise | C8: 0 | D8: 0 | E8: 0 | F8: 0 | G8: 175000
B9: Boutique ARR Total | C9: =SUM(C4:C8) -> 45000 | D9: =SUM(D4:D8) -> 81000 | E9: =SUM(E4:E8) -> 153000 | F9: =SUM(F4:F8) -> 303000 | G9: =SUM(G4:G8) -> 691000
B11: VEKTOR : HOUSE — ANNUAL RECURRING REVENUE (USD)
B12: Commercial clients (Alloy Partners) | C12: 0 | D12: 0 | E12: 0 | F12: 200000 | G12: 400000
B13: House ARR Total | C13: =C12 -> 0 | D13: =D12 -> 0 | E13: =E12 -> 0 | F13: =F12 -> 200000 | G13: =G12 -> 400000
B15: VEKTOR : WRAPPED — LICENCE REVENUE (USD)
B16: Platform licence fees | C16: 0 | D16: 0 | E16: 0 | F16: 0 | G16: 120000
B17: Per-mandate fees | C17: 0 | D17: 0 | E17: 0 | F17: 0 | G17: 37500
B18: Wrapped Revenue Total | C18: =C16+C17 -> 0 | D18: =D16+D17 -> 0 | E18: =E16+E17 -> 0 | F18: =F16+F17 -> 0 | G18: =G16+G17 -> 157500
B20: TOTAL ARR (USD)
B21: Total ARR | C21: =C9+C13+C18 -> 45000 | D21: =D9+D13+D18 -> 81000 | E21: =E9+E13+E18 -> 153000 | F21: =F9+F13+F18 -> 503000 | G21: =G9+G13+G18 -> 1248500
B23: OPERATING COSTS (USD) — constant across years (update as needed)
B24: Total operating costs | C24: 981000 | D24: 1079100 | E24: 1243420 | F24: 1490140 | G24: 1791114
B25: EBITDA | C25: =C21-C24 -> -936000 | D25: =D21-D24 -> -998100 | E25: =E21-E24 -> -1090420 | F25: =F21-F24 -> -987140 | G25: =G21-G24 -> -542614
B26: EBITDA margin | C26: =IF(C21=0,"n/m",C25/C21) -> -20.8 | D26: =IF(D21=0,"n/m",D25/D21) -> -12.322222 | E26: =IF(E21=0,"n/m",E25/E21) -> -7.1269281 | F26: =IF(F21=0,"n/m",F25/F21) -> -1.962505 | G26: =IF(G21=0,"n/m",G25/G21) -> -0.43461274
B28: RAISE — CONTEXT
B29: Raise target | C29: US$2.5M
B30: Pre-money range | C30: US$9M – US$10M
B31: Runway (base case) | C31: 18–24 months post-raise
B32: Use of proceeds | C32: 5-person team · institutional sales cycle · legal infrastructure · Tenzor design phase

Sheet Bull Case
B1: VEKTOR — BULL CASE | C1: Year 1 (2026) | D1: Year 2 (2027) | E1: Year 3 (2028) | F1: Year 4 (2029) | G1: Year 5 (2030)
B3: VEKTOR : BOUTIQUE — ANNUAL RECURRING REVENUE (USD)
B4: Proof Partners | C4: 67500 | D4: 67500 | E4: 67500 | F4: 0 | G4: 0
B5: Entry | C5: 72000 | D5: 144000 | E5: 252000 | F5: 360000 | G5: 468000
B6: Growth | C6: 36000 | D6: 72000 | E6: 180000 | F6: 288000 | G6: 432000
B7: Institutional | C7: 0 | D7: 105000 | E7: 210000 | F7: 420000 | G7: 630000
B8: Enterprise | C8: 0 | D8: 0 | E8: 175000 | F8: 350000 | G8: 525000
B9: Boutique ARR Total | C9: =SUM(C4:C8) -> 175500 | D9: =SUM(D4:D8) -> 388500 | E9: =SUM(E4:E8) -> 884500 | F9: =SUM(F4:F8) -> 1418000 | G9: =SUM(G4:G8) -> 2055000
B11: VEKTOR : HOUSE — ANNUAL RECURRING REVENUE (USD)
B12: Commercial clients (Alloy Partners) | C12: 0 | D12: 0 | E12: 600000 | F12: 900000 | G12: 1200000
B13: House ARR Total | C13: =C12 -> 0 | D13: =D12 -> 0 | E13: =E12 -> 600000 | F13: =F12 -> 900000 | G13: =G12 -> 1200000
B15: VEKTOR : WRAPPED — LICENCE REVENUE (USD)
B16: Platform licence fees | C16: 0 | D16: 0 | E16: 180000 | F16: 360000 | G16: 540000
B17: Per-mandate fees | C17: 0 | D17: 0 | E17: 150000 | F17: 300000 | G17: 450000
B18: Wrapped Revenue Total | C18: =C16+C17 -> 0 | D18: =D16+D17 -> 0 | E18: =E16+E17 -> 330000 | F18: =F16+F17 -> 660000 | G18: =G16+G17 -> 990000
B20: TOTAL ARR (USD)
B21: Total ARR | C21: =C9+C13+C18 -> 175500 | D21: =D9+D13+D18 -> 388500 | E21: =E9+E13+E18 -> 1814500 | F21: =F9+F13+F18 -> 2978000 | G21: =G9+G13+G18 -> 4245000
B23: OPERATING COSTS (USD) — constant across years (update as needed)
B24: Total operating costs | C24: 1405000 | D24: 1545500 | E24: 1780675 | F24: 2134130 | G24: 2564976
B25: EBITDA | C25: =C21-C24 -> -1229500 | D25: =D21-D24 -> -1157000 | E25: =E21-E24 -> 33825 | F25: =F21-F24 -> 843870 | G25: =G21-G24 -> 1680024
B26: EBITDA margin | C26: =IF(C21=0,"n/m",C25/C21) -> -7.005698 | D26: =IF(D21=0,"n/m",D25/D21) -> -2.978121 | E26: =IF(E21=0,"n/m",E25/E21) -> 0.018641499 | F26: =IF(F21=0,"n/m",F25/F21) -> 0.28336803 | G26: =IF(G21=0,"n/m",G25/G21) -> 0.39576537
B28: RAISE — CONTEXT
B29: Raise target | C29: US$2.5M
B30: Pre-money range | C30: US$9M – US$10M
B31: Runway (base case) | C31: 18–24 months post-raise
B32: Use of proceeds | C32: 5-person team · institutional sales cycle · legal infrastructure · Tenzor design phase

Sheet Summary
B1: SCENARIO SUMMARY | C1: Year 1 | D1: Year 2 | E1: Year 3 | F1: Year 4 | G1: Year 5
B3: BASE CASE
B4: Total ARR | C4: 76500 | D4: 166500 | E4: 877500 | F4: 1493000 | G4: 2520000
B5: EBITDA | C5: -1103500 | D5: -1131500 | E5: -618050 | F5: -299380 | G5: 365724
B6: EBITDA margin | C6: -14.424837 | D6: -6.7957958 | E6: -0.70433048 | F6: -0.20052244 | G6: 0.14512857
B8: BEAR CASE
B9: Total ARR | C9: 45000 | D9: 81000 | E9: 153000 | F9: 503000 | G9: 1248500
B10: EBITDA | C10: -936000 | D10: -998100 | E10: -1090420 | F10: -987140 | G10: -542614
B11: EBITDA margin | C11: -20.8 | D11: -12.322222 | E11: -7.1269281 | F11: -1.962505 | G11: -0.43461274
B13: BULL CASE
B14: Total ARR | C14: 175500 | D14: 388500 | E14: 1814500 | F14: 2978000 | G14: 4245000
B15: EBITDA | C15: -1229500 | D15: -1157000 | E15: 33825 | F15: 843870 | G15: 1680024
B16: EBITDA margin | C16: -7.005698 | D16: -2.978121 | E16: 0.018641499 | F16: 0.28336803 | G16: 0.39576537
B19: Costs scale at +10% p.a. Year 1→2, +15% Year 2→3, +20% thereafter as headcount grows.
B20: House and Wrapped revenue begin Year 3 (Base) — 12–18 month institutional sales cycle.
A22: TENZOR SCENARIO (conservative base — see Tenzor Scenario tab)
A23: Combined Revenue (Vektor Base + Tenzor) | B23: ='Tenzor Scenario'!C44 -> 1576500 | C23: ='Tenzor Scenario'!D44 -> 1666500 | D23: ='Tenzor Scenario'!E44 -> 2377500 | E23: ='Tenzor Scenario'!F44 -> 2993000 | F23: ='Tenzor Scenario'!G44 -> 4020000
A24: Combined EBITDA | B24: ='Tenzor Scenario'!C50 -> 396500 | C24: ='Tenzor Scenario'!D50 -> 368500 | D24: ='Tenzor Scenario'!E50 -> -190050 | E24: ='Tenzor Scenario'!F50 -> 104620 | F24: ='Tenzor Scenario'!G50 -> 585724

Sheet Tenzor Scenario
B1: TENZOR — INSTITUTIONAL PRODUCT ROADMAP | C1: NDA CONFIDENTIAL — NOT FOR EXTERNAL DISTRIBUTION
B3: TENZOR CONTEXT
B4: Product | C4: Tenzor — full institutional portfolio management platform. Same systematic methodology as Vektor extended to serve DPM desks at regional banks, large MFOs, and institutional asset managers.
B5: Sequencing | C5: Development begins post first Vektor Proof Partners go-live. Series A funded. Not in development concurrently with Vektor.
B6: Series A trigger | C6: First Vektor Proof Partners live · Alloy Partners Stage 2 active · Tenzor design phase complete
B7: Series A size | C7: US$4M – US$5M (indicative) · to fund Tenzor development team + expanded commercial infrastructure
B8: Market context | C8: Temenos TripleA Plus: US$150K–US$400K+ per deployment. Avaloq: US$500K–US$2M+ implementation. Tenzor enters below both at mid-market institutional pricing.
B9: TAM (combined) | C9: ~US$25M–US$30M ARR at 10% penetration across SG, CH, UK (Vektor + Tenzor non-overlapping, conservative)
B11: TENZOR ASSUMPTIONS — CONSERVATIVE BASE CASE
C12: Year 1 (2026) | D12: Year 2 (2027) | E12: Year 3 (2028) | F12: Year 4 (2029) | G12: Year 5 (2030)
B13: TENZOR PRICING (USD/year) — indicative
B14: Tenzor Standard (up to US$500M AUM) | C14: 300000 | D14: 300000 | E14: 300000 | F14: 300000 | G14: 300000 | H14: Below Temenos/Avaloq floor · mid-market institutional pricing
B15: Tenzor Growth (US$500M–US$2B AUM) | C15: 480000 | D15: 480000 | E15: 480000 | F15: 480000 | G15: 480000 | H15: Below Temenos/Avaloq floor · mid-market institutional pricing
B16: Tenzor Institutional (US$2B+ AUM) | C16: 720000 | D16: 720000 | E16: 720000 | F16: 720000 | G16: 720000 | H16: Below Temenos/Avaloq floor · mid-market institutional pricing
B18: TENZOR CLIENT RAMP (cumulative, end of year)
B19: Note: Development Years 1–3 (Vektor first). Tenzor clients from Year 4 only. Numbers to be updated as Vektor Proof Partners go-live and Series A timeline becomes clear.
B20: Tenzor Standard clients | C20: 300000 | D20: 300000 | E20: 300000 | F20: 300000 | G20: 300000
B21: Tenzor Growth clients | C21: 480000 | D21: 480000 | E21: 480000 | F21: 480000 | G21: 480000
B22: Tenzor Institutional clients | C22: 720000 | D22: 720000 | E22: 720000 | F22: 720000 | G22: 720000
B24: TENZOR ADDITIONAL COSTS FROM SERIES A (USD/year)
B25: Additional team (est. +8 people from Y3) | C25: 0 | D25: 0 | E25: 840000 | F25: 840000 | G25: 960000
B26: Additional infrastructure | C26: 0 | D26: 0 | E26: 72000 | F26: 96000 | G26: 120000
B27: Legal + compliance (Tenzor-specific) | C27: 0 | D27: 0 | E27: 80000 | F27: 60000 | G27: 60000
B28: Additional sales + marketing | C28: 0 | D28: 0 | E28: 80000 | F28: 100000 | G28: 140000
B30: TENZOR REVENUE (USD)
B31: Tenzor Standard revenue | C31: 300000 | D31: 300000 | E31: 300000 | F31: 300000 | G31: 300000
B32: Tenzor Growth revenue | C32: 480000 | D32: 480000 | E32: 480000 | F32: 480000 | G32: 480000
B33: Tenzor Institutional revenue | C33: 720000 | D33: 720000 | E33: 720000 | F33: 720000 | G33: 720000
B34: Tenzor Revenue Total | C34: =SUM(C31:C33) -> 1500000 | D34: =SUM(D31:D33) -> 1500000 | E34: =SUM(E31:E33) -> 1500000 | F34: =SUM(F31:F33) -> 1500000 | G34: =SUM(G31:G33) -> 1500000
B36: Tenzor Additional Costs Total | C36: =SUM(C25:C28) -> 0 | D36: =SUM(D25:D28) -> 0 | E36: =SUM(E25:E28) -> 1072000 | F36: =SUM(F25:F28) -> 1096000 | G36: =SUM(G25:G28) -> 1280000
B39: COMBINED MODEL — VEKTOR (BASE CASE) + TENZOR | C39: (Conservative · Base Vektor + Conservative Tenzor)
C41: Year 1 (2026) | D41: Year 2 (2027) | E41: Year 3 (2028) | F41: Year 4 (2029) | G41: Year 5 (2030)
B42: Vektor Revenue (Base Case) | C42: ='Base Case'!C21 -> 76500 | D42: ='Base Case'!D21 -> 166500 | E42: ='Base Case'!E21 -> 877500 | F42: ='Base Case'!F21 -> 1493000 | G42: ='Base Case'!G21 -> 2520000
B43: Tenzor Revenue | C43: =C34 -> 1500000 | D43: =D34 -> 1500000 | E43: =E34 -> 1500000 | F43: =F34 -> 1500000 | G43: =G34 -> 1500000
B44: Total Combined Revenue | C44: =SUM(C42:C43) -> 1576500 | D44: =SUM(D42:D43) -> 1666500 | E44: =SUM(E42:E43) -> 2377500 | F44: =SUM(F42:F43) -> 2993000 | G44: =SUM(G42:G43) -> 4020000
B46: Vektor Operating Costs (Base Case) | C46: ='Base Case'!C24 -> 1180000 | D46: ='Base Case'!D24 -> 1298000 | E46: ='Base Case'!E24 -> 1495550 | F46: ='Base Case'!F24 -> 1792380 | G46: ='Base Case'!G24 -> 2154276
B47: Tenzor Additional Costs | C47: =C36 -> 0 | D47: =D36 -> 0 | E47: =E36 -> 1072000 | F47: =F36 -> 1096000 | G47: =G36 -> 1280000
B48: Total Combined Costs | C48: =C46+C47 -> 1180000 | D48: =D46+D47 -> 1298000 | E48: =E46+E47 -> 2567550 | F48: =F46+F47 -> 2888380 | G48: =G46+G47 -> 3434276
B50: Combined EBITDA | C50: =C44-C48 -> 396500 | D50: =D44-D48 -> 368500 | E50: =E44-E48 -> -190050 | F50: =F44-F48 -> 104620 | G50: =G44-G48 -> 585724
B51: Combined EBITDA margin | C51: =IF(C44=0,"n/m",C50/C44) -> 0.2515065 | D51: =IF(D44=0,"n/m",D50/D44) -> 0.22112211 | E51: =IF(E44=0,"n/m",E50/E44) -> -0.079936909 | F51: =IF(F44=0,"n/m",F50/F44) -> 0.034954895 | G51: =IF(G44=0,"n/m",G50/G44) -> 0.14570249
...
